---
tags:
  - leetcode/problem
questionId: '2650'
title: Design Cancellable Function
translatedTitle: 设计可取消函数
titleSlug: design-cancellable-function
aliases:
  - Design Cancellable Function
  - design-cancellable-function
  - 设计可取消函数
lcLink: https://leetcode.com/problems/design-cancellable-function/
lcTopics: []
lcDifficulty: Hard
lcAcRate: 51.9%
similarQuestions:
  - '[[2648.generate-fibonacci-sequence|2648.生成斐波那契数列]]'
  - '[[2649.nested-array-generator|2649.嵌套数组生成器]]'
grade: ⭐⭐⭐
likes: 72
dislikes: 15
favorites: []
solutions: []
notes: []
cssclasses: []
created: 2024-08-13 00:10
updated:
---

**Nav:** << previous: [[2649.nested-array-generator]] | next: [[2651.calculate-delayed-arrival-time]] >>

---

## Description

~~~tabs
tab: English

<p>Sometimes you have a long running task, and you may wish to cancel it before it completes. To help with this goal, write a function&nbsp;<code>cancellable</code> that accepts a generator object and returns an array of two values: a <strong>cancel function</strong> and a <strong>promise</strong>.</p>

<p>You may assume the generator function will only&nbsp;yield promises. It is your function&#39;s responsibility to pass the values resolved by the promise back to the generator. If the promise rejects, your function should throw that&nbsp;error back to the generator.</p>

<p>If the cancel callback is called before the generator is done, your function should throw an error back to the generator. That error should be the string&nbsp;<code>&quot;Cancelled&quot;</code>&nbsp;(Not an <code>Error</code>&nbsp;object). If the error was caught, the returned&nbsp;promise should resolve with the next value that was yielded or returned. Otherwise, the promise should reject with the thrown error. No more code should be executed.</p>

<p>When the generator is done, the promise your function returned should resolve the value the generator returned. If, however, the generator throws an error, the returned promise should reject with the error.</p>

<p>An example of how your code would be used:</p>

<pre>
function* tasks() {
  const val = yield new Promise(resolve =&gt; resolve(2 + 2));
  yield new Promise(resolve =&gt; setTimeout(resolve, 100));
  return val + 1; // calculation shouldn&#39;t be done.
}
const [cancel, promise] = cancellable(tasks());
setTimeout(cancel, 50);
promise.catch(console.log); // logs &quot;Cancelled&quot; at t=50ms
</pre>

<p>If&nbsp;instead&nbsp;<code>cancel()</code> was not called or was called after <code>t=100ms</code>, the promise would&nbsp;have resolved&nbsp;<code>5</code>.</p>

<p>&nbsp;</p>
<p><strong class="example">Example 1:</strong></p>

<pre>
<strong>Input:</strong> 
generatorFunction = function*() { 
&nbsp; return 42; 
}
cancelledAt = 100
<strong>Output:</strong> {&quot;resolved&quot;: 42}
<strong>Explanation:</strong>
const generator = generatorFunction();
const [cancel, promise] = cancellable(generator);
setTimeout(cancel, 100);
promise.then(console.log); // resolves 42 at t=0ms

The generator immediately yields 42 and finishes. Because of that, the returned promise immediately resolves 42. Note that cancelling a finished generator does nothing.
</pre>

<p><strong class="example">Example 2:</strong></p>

<pre>
<strong>Input:</strong>
generatorFunction = function*() { 
&nbsp; const msg = yield new Promise(res =&gt; res(&quot;Hello&quot;)); 
&nbsp; throw `Error: ${msg}`; 
}
cancelledAt = null
<strong>Output:</strong> {&quot;rejected&quot;: &quot;Error: Hello&quot;}
<strong>Explanation:</strong>
A promise is yielded. The function handles this by waiting for it to resolve and then passes the resolved value back to the generator. Then an error is thrown which has the effect of causing the promise to reject with the same thrown error.
</pre>

<p><strong class="example">Example 3:</strong></p>

<pre>
<strong>Input:</strong> 
generatorFunction = function*() { 
&nbsp; yield new Promise(res =&gt; setTimeout(res, 200)); 
&nbsp; return &quot;Success&quot;; 
}
cancelledAt = 100
<strong>Output:</strong> {&quot;rejected&quot;: &quot;Cancelled&quot;}
<strong>Explanation:</strong>
While the function is waiting for the yielded promise to resolve, cancel() is called. This causes an error message to be sent back to the generator. Since this error is uncaught, the returned promise rejected with this error.
</pre>

<p><strong class="example">Example 4:</strong></p>

<pre>
<strong>Input:</strong>
generatorFunction = function*() { 
&nbsp; let result = 0; 
&nbsp; yield new Promise(res =&gt; setTimeout(res, 100));
&nbsp; result += yield new Promise(res =&gt; res(1)); 
&nbsp; yield new Promise(res =&gt; setTimeout(res, 100)); 
&nbsp; result += yield new Promise(res =&gt; res(1)); 
&nbsp; return result;
}
cancelledAt = null
<strong>Output:</strong> {&quot;resolved&quot;: 2}
<strong>Explanation:</strong>
4 promises are yielded. Two of those promises have their values added to the result. After 200ms, the generator finishes with a value of 2, and that value is resolved by the returned promise.
</pre>

<p><strong class="example">Example 5:</strong></p>

<pre>
<strong>Input:</strong> 
generatorFunction = function*() { 
&nbsp; let result = 0; 
&nbsp; try { 
&nbsp;   yield new Promise(res =&gt; setTimeout(res, 100)); 
&nbsp;   result += yield new Promise(res =&gt; res(1)); 
&nbsp;   yield new Promise(res =&gt; setTimeout(res, 100)); 
&nbsp;   result += yield new Promise(res =&gt; res(1)); 
&nbsp; } catch(e) { 
&nbsp;   return result; 
&nbsp; } 
&nbsp; return result; 
}
cancelledAt = 150
<strong>Output:</strong> {&quot;resolved&quot;: 1}
<strong>Explanation:</strong>
The first two yielded promises resolve and cause the result to increment. However, at t=150ms, the generator is cancelled. The error sent to the generator is caught and the result is returned and finally resolved by the returned promise.
</pre>

<p><strong class="example">Example 6:</strong></p>

<pre>
<strong>Input:</strong> 
generatorFunction = function*() { 
&nbsp; try { 
&nbsp;   yield new Promise((resolve, reject) =&gt; reject(&quot;Promise Rejected&quot;)); 
&nbsp; } catch(e) { 
&nbsp;   let a = yield new Promise(resolve =&gt; resolve(2));
    let b = yield new Promise(resolve =&gt; resolve(2)); 
&nbsp;   return a + b; 
&nbsp; }; 
}
cancelledAt = null
<strong>Output:</strong> {&quot;resolved&quot;: 4}
<strong>Explanation:</strong>
The first yielded promise immediately rejects. This error is caught. Because the generator hasn&#39;t been cancelled, execution continues as usual. It ends up resolving 2 + 2 = 4.</pre>

<p>&nbsp;</p>
<p><strong>Constraints:</strong></p>

<ul>
	<li><code>cancelledAt == null or 0 &lt;= cancelledAt &lt;= 1000</code></li>
	<li><code>generatorFunction</code> returns a generator object</li>
</ul>


> [!tip]- Hint 1
> This question tests understanding of two-way communication between generator functions and the code that evaluates the generator. It is a powerful technique which is used in libraries such as redux-saga.



> [!tip]- Hint 2
> You can pass a value value to a generator function X by calling generator.next(X). Then in the generator function, you can access this value by calling let X = yield "val to pass into generator.next()";



> [!tip]- Hint 3
> You can throw an error back to a generator function by calling generator.throw(err). If this error isn't caught in the generator function, that will throw an error.



---

[submissions](https://leetcode.com/problems/design-cancellable-function/submissions/) | [solutions](https://leetcode.com/problems/design-cancellable-function/solutions/)


tab: 中文

<p>有时候你会有一个长时间运行的任务，并且你可能希望在它完成之前取消它。为了实现这个目标，请你编写一个名为 <code>cancellable</code> 的函数，它接收一个生成器对象，并返回一个包含两个值的数组：一个 <strong>取消函数</strong> 和一个 <strong>promise</strong> 对象。</p>

<p>你可以假设生成器函数只会生成 promise 对象。你的函数负责将 promise 对象解析的值传回生成器。如果 promise 被拒绝，你的函数应将该错误抛回给生成器。</p>

<p>如果在生成器完成之前调用了取消回调函数，则你的函数应该将错误抛回给生成器。该错误应该是字符串 <code>"Cancelled"</code>（而不是一个 <code>Error</code> 对象）。如果错误被捕获，则返回的 promise 应该解析为下一个生成或返回的值。否则，promise 应该被拒绝并抛出该错误。不应执行任何其他代码。</p>

<p>当生成器完成时，您的函数返回的 promise 应该解析为生成器返回的值。但是，如果生成器抛出错误，则返回的 promise 应该拒绝并抛出该错误。</p>

<p>下面的示例展示了你的代码会如何被使用：</p>

<pre>
function* tasks() {
  const val = yield new Promise(resolve =&gt; resolve(2 + 2));
  yield new Promise(resolve =&gt; setTimeout(resolve, 100));
  return val + 1; // calculation shouldn't be done.
}
const [cancel, promise] = cancellable(tasks());
setTimeout(cancel, 50);
promise.catch(console.log); // logs "Cancelled" at t=50ms
</pre>

<p>相反，如果 <code>cancel()</code> 没有被调用或者在 <code>t=100ms</code> 之后才被调用，那么 promise 应被解析为 <code>5</code> 。</p>

<p>&nbsp;</p>

<p><strong>示例 1：</strong></p>

<pre>
<strong>输入：</strong>
generatorFunction = function*() { 
&nbsp; return 42; 
}
cancelledAt = 100
<strong>输出：</strong>{"resolved": 42}
<strong>解释：</strong>
const generator = generatorFunction();
const [cancel, promise] = cancellable(generator);
setTimeout(cancel, 100);
promise.then(console.log); // 在 t=0ms 解析为 42

该生成器立即生成 42 并完成。因此，返回的 promise 立即解析为 42。请注意，取消已经完成的生成器没有任何作用。
</pre>

<p><strong>示例 2：</strong></p>

<pre>
<strong>输入：</strong>
generatorFunction = function*() { 
&nbsp; const msg = yield new Promise(res =&gt; res("Hello")); 
&nbsp; throw `Error: ${msg}`; 
}
cancelledAt = null
<strong>输出：</strong>{"rejected": "Error: Hello"}
<strong>解释：</strong>
一个 Promise 被生成。该函数通过等待 promise 解析并将解析后的值传回生成器来处理它。然后抛出一个错误，这会导致 promise 被同样抛出的错误拒绝。
</pre>

<p><strong>示例 3：</strong></p>

<pre>
<strong>输入：</strong>
generatorFunction = function*() { 
&nbsp; yield new Promise(res =&gt; setTimeout(res, 200)); 
&nbsp; return "Success"; 
}
cancelledAt = 100
<strong>输出：</strong>{"rejected": "Cancelled"}
<strong>解释：</strong>
当函数等待被生成的 promise 解析时，cancel() 被调用。这会导致一个错误消息被发送回生成器。由于这个错误没有被捕获，返回的 promise 会因为这个错误而被拒绝。
</pre>

<p><strong>示例 4：</strong></p>

<pre>
<strong>输入：</strong>
generatorFunction = function*() { 
&nbsp; let result = 0; 
&nbsp; yield new Promise(res =&gt; setTimeout(res, 100));
&nbsp; result += yield new Promise(res =&gt; res(1)); 
&nbsp; yield new Promise(res =&gt; setTimeout(res, 100)); 
&nbsp; result += yield new Promise(res =&gt; res(1)); 
&nbsp; return result;
}
cancelledAt = null
<strong>输出：</strong>{"resolved": 2}
<strong>解释：</strong>
生成器生成了 4 个 promise 。其中两个 promise 的值被添加到结果中。200ms 后，生成器以值 2 完成，该值被返回的 promise 解析。
</pre>

<p><strong>示例 5：</strong></p>

<pre>
<strong>输入：</strong>
generatorFunction = function*() { 
&nbsp; let result = 0; 
&nbsp; try { 
&nbsp;   yield new Promise(res =&gt; setTimeout(res, 100)); 
&nbsp;   result += yield new Promise(res =&gt; res(1)); 
&nbsp;   yield new Promise(res =&gt; setTimeout(res, 100)); 
&nbsp;   result += yield new Promise(res =&gt; res(1)); 
&nbsp; } catch(e) { 
&nbsp;   return result; 
&nbsp; } 
&nbsp; return result; 
}
cancelledAt = 150
<strong>输出：</strong>{"resolved": 1}
<strong>解释：</strong>
前两个生成的 promise 解析并导致结果递增。然而，在 t=150ms 时，生成器被取消了。发送给生成器的错误被捕获，结果被返回并最终由返回的 promise 解析。
</pre>

<p><strong>示例 6：</strong></p>

<pre>
<strong>输入：</strong>
generatorFunction = function*() { 
&nbsp; try { 
&nbsp;   yield new Promise((resolve, reject) =&gt; reject("Promise Rejected")); 
&nbsp; } catch(e) { 
&nbsp;   let a = yield new Promise(resolve =&gt; resolve(2));
    let b = yield new Promise(resolve =&gt; resolve(2)); 
&nbsp;   return a + b; 
&nbsp; }; 
}
cancelledAt = null
<strong>输出：</strong>{"resolved": 4}
<strong>解释：</strong>
第一个生成的 promise 立即被拒绝。该错误被捕获。因为生成器没有被取消，执行继续像往常一样。最终解析为 2 + 2 = 4。</pre>

<p>&nbsp;</p>

<p><strong>提示：</strong></p>

<ul>
	<li><code>cancelledAt == null or 0 &lt;= cancelledAt &lt;= 1000</code></li>
	<li><code>generatorFunction</code> 返回一个生成器对象</li>
</ul>


> [!tip]- 提示 1
> This question tests understanding of two-way communication between generator functions and the code that evaluates the generator. It is a powerful technique which is used in libraries such as redux-saga.




> [!tip]- 提示 2
> You can pass a value value to a generator function X by calling generator.next(X). Then in the generator function, you can access this value by calling let X = yield "val to pass into generator.next()";




> [!tip]- 提示 3
> You can throw an error back to a generator function by calling generator.throw(err). If this error isn't caught in the generator function, that will throw an error.




---

[提交记录](https://leetcode.cn/problems/design-cancellable-function/submissions/) | [题解](https://leetcode.cn/problems/design-cancellable-function/solution/)


~~~

## Code Snippets

~~~tabs
tab: JavaScript

```javascript
/**
 * @param {Generator} generator
 * @return {[Function, Promise]}
 */
var cancellable = function(generator) {
    
};

/**
 * function* tasks() {
 *   const val = yield new Promise(resolve => resolve(2 + 2));
 *   yield new Promise(resolve => setTimeout(resolve, 100));
 *   return val + 1;
 * }
 * const [cancel, promise] = cancellable(tasks());
 * setTimeout(cancel, 50);
 * promise.catch(console.log); // logs "Cancelled" at t=50ms
 */
```

tab: TypeScript

```typescript
function cancellable<T>(generator: Generator<Promise<any>, T, unknown>): [() => void, Promise<T>] {
    
};

/**
 * function* tasks() {
 *   const val = yield new Promise(resolve => resolve(2 + 2));
 *   yield new Promise(resolve => setTimeout(resolve, 100));
 *   return val + 1;
 * }
 * const [cancel, promise] = cancellable(tasks());
 * setTimeout(cancel, 50);
 * promise.catch(console.log); // logs "Cancelled" at t=50ms
 */
```

~~~

## Similar Questions

```dataviewjs
const currentFilePath = dv.current().file.path;
dv.table(
    ["题号", "标题", "标题(中)", "分类",  "难度", "通过率", "评分", "解法", "笔记", "收藏"],
    dv.pages("#leetcode/problem")
        .filter(p => p.similarQuestions && p.similarQuestions.some(q => q.path === currentFilePath))
        .map((p) => [p.file.link, p.title, p.translatedTitle, p.lcTopics, p.lcDifficulty, p.lcAcRate, p.grade, p.solutions, p.notes, p.favorites])
);
```

## Solutions

```dataviewjs
const currentDir = dv.current().file.folder;
const solutionPages = dv.pages(`"${currentDir}" and #leetcode/solution`);
dv.table(
    ["解法", "描述", "编程语言", "评分", "相关链接", "最后更新"],
    solutionPages
        .map((p) => [p.file.link, p.desc, p.program_language,p.grade, p.related_links, p.updated])
);
//  更新 solutions 元信息
const currentFile = app.vault.getAbstractFileByPath(dv.current().file.path);
let solutionList = solutionPages.map(p => `[[${p.file.link.path}|${p.file.name}]]`).array();
await app.fileManager.processFrontMatter(currentFile, (fm) => {
  fm["solutions"] = solutionList;
});
```

## Notes

```dataviewjs
const currentFilePath = dv.current().file.path;
let notePages = dv.pages(`#leetcode/note`)
	.filter(p => p.related_questions && p.related_questions.some(q => q.path === currentFilePath));
dv.table(["笔记", "标题", "描述", "评分", "最后更新"],
  notePages.map(p => [p.file.link, p.title, p.desc, p.grade, p.updated])
);
// 更新 notes 元信息
const currentFile = app.vault.getAbstractFileByPath(currentFilePath);
let noteList = notePages.map(p => `[[${p.file.link.path}|${p.file.name}]]`).array();
await app.fileManager.processFrontMatter(currentFile, (fm) => {
  fm["notes"] = noteList;
});
```
          
